<mujoco model="G1">
  <compiler angle="radian"/>

  <asset>
    <mesh name="base_link" file="meshes/base_link.STL"/>
    <mesh name="ll1" file="meshes/ll1.STL"/>
    <mesh name="ll2" file="meshes/ll2.STL"/>
    <mesh name="ll3" file="meshes/ll3.STL"/>
    <mesh name="ll4" file="meshes/ll4.STL"/>
    <mesh name="ll5" file="meshes/ll5.STL"/>
    <mesh name="ll6" file="meshes/ll6.STL"/>
    <mesh name="ll7" file="meshes/ll7.STL"/>
    <mesh name="rl1" file="meshes/rl1.STL"/>
    <mesh name="rl2" file="meshes/rl2.STL"/>
    <mesh name="rl3" file="meshes/rl3.STL"/>
    <mesh name="rl4" file="meshes/rl4.STL"/>
    <mesh name="rl5" file="meshes/rl5.STL"/>
    <mesh name="rl6" file="meshes/rl6.STL"/>
    <mesh name="rl7" file="meshes/rl7.STL"/>
  </asset>

  <worldbody>
    <geom type="mesh" rgba="1 1 1 1" mesh="base_link"/>
    <body name="ll1" pos="0 0.082178 0.023564" quat="0.564729 -0.425536 -0.425534 -0.564731">
      <inertial pos="-0.00683857 -0.00760062 0.0356956" quat="0.737971 0.0926788 -0.316223 0.588908" mass="0.074722" diaginertia="2.92466e-05 2.64685e-05 1.5556e-05"/>
      <joint name="lj1" pos="0 0 0" axis="0 0 1"/>
      <geom type="mesh" rgba="1 1 1 1" mesh="ll1"/>
      <body name="ll2" pos="-0.013831 0.009 0.056483" quat="-0.0984121 0.0984066 -0.700227 -0.700224">
        <inertial pos="0.0426643 0.00335833 0.00195675" quat="0.0153791 0.819645 0.110573 0.561889" mass="0.0802646" diaginertia="4.2423e-05 4.02991e-05 1.71232e-05"/>
        <joint name="lj2" pos="0 0 0" axis="0 0 1"/>
        <geom type="mesh" rgba="1 1 1 1" mesh="ll2"/>
        <body name="ll3" pos="0.096 0.00675 -0.009" quat="0.499998 -0.5 0.500002 -0.5">
          <inertial pos="-0.00813645 -0.00681486 0.0512519" quat="0.978445 0.0932047 -0.161619 0.0885248" mass="0.0836531" diaginertia="5.12591e-05 4.84119e-05 1.67651e-05"/>
          <joint name="lj3" pos="0 0 0" axis="0 0 -1"/>
          <geom type="mesh" rgba="1 1 1 1" mesh="ll3"/>
          <body name="ll4" pos="0.011 -0.01578 0.0878" quat="0.000563312 0.707388 -0.000562864 0.706825">
            <inertial pos="0.00766611 0.0628075 -0.0294342" quat="0.0343313 0.711017 0.0573579 0.69999" mass="0.187099" diaginertia="0.000224941 0.000166914 9.42823e-05"/>
            <joint name="lj4" pos="0 0 0" axis="0 0 -1"/>
            <geom type="mesh" rgba="1 1 1 1" mesh="ll4"/>
            <body name="ll5" pos="0.01 0.086 -0.013" quat="-2.59734e-06 -2.59735e-06 0.707108 0.707105">
              <inertial pos="-0.000165239 -0.00261491 0.0359689" quat="0.683937 0.139165 -0.164159 0.697077" mass="0.0700036" diaginertia="2.47968e-05 2.14462e-05 1.42914e-05"/>
              <joint name="lj5" pos="0 0 0" axis="0 0 1"/>
              <geom type="mesh" rgba="1 1 1 1" mesh="ll5"/>
              <body name="ll6" pos="0 0.016 0.0568" quat="0.500198 -0.5002 0.4998 0.499802">
                <inertial pos="-0.024677 -0.0103039 -0.000889487" quat="0.317954 0.352197 0.382093 0.793012" mass="0.075765" diaginertia="3.94874e-05 3.86145e-05 1.53133e-05"/>
                <joint name="lj6" pos="0 0 0" axis="0 0 -1"/>
                <geom type="mesh" rgba="1 1 1 1" mesh="ll6"/>
                <body name="ll7" pos="-0.046 0.006 -0.016" quat="-2.59734e-06 -2.59735e-06 0.707108 0.707105">
                  <inertial pos="0.0501035 -0.0207212 -0.000893441" quat="0.398128 0.701636 0.46819 0.360554" mass="0.0739845" diaginertia="0.000164858 0.00014925 3.18554e-05"/>
                  <joint name="lj7" pos="0 0 0" axis="0 0 -1"/>
                  <geom type="mesh" rgba="1 1 1 1" mesh="ll7"/>
                </body>
              </body>
            </body>
          </body>
        </body>
      </body>
    </body>
    <body name="rl1" pos="0 -0.082178 0.023564" quat="0.564729 0.425536 0.425534 -0.564731">
      <inertial pos="0.00683467 -0.00759986 0.0356982" quat="0.58916 0.316383 -0.0925146 0.737721" mass="0.0747186" diaginertia="2.92447e-05 2.64731e-05 1.5554e-05"/>
      <joint name="rj1" pos="0 0 0" axis="0 0 -1"/>
      <geom type="mesh" rgba="1 1 1 1" mesh="rl1"/>
      <body name="rl2" pos="0.013831 0.009 0.056483" quat="0.0983429 -0.0984756 -0.699771 -0.700679">
        <inertial pos="-0.0426643 0.00335578 0.00196106" quat="0.110216 0.561961 0.0148572 0.819654" mass="0.0802643" diaginertia="4.24229e-05 4.0299e-05 1.71232e-05"/>
        <joint name="rj2" pos="0 0 0" axis="0 0 1"/>
        <geom type="mesh" rgba="1 1 1 1" mesh="rl2"/>
        <body name="rl3" pos="-0.096 0.0067615 -0.0089914" quat="0.500318 -0.49968 -0.500321 0.49968">
          <inertial pos="0.00813646 -0.00681482 0.0512518" quat="0.978446 0.093205 0.161619 -0.0885232" mass="0.0836535" diaginertia="5.12591e-05 4.84119e-05 1.67651e-05"/>
          <joint name="rj3" pos="0 0 0" axis="0 0 -1"/>
          <geom type="mesh" rgba="1 1 1 1" mesh="rl3"/>
          <body name="rl4" pos="-0.011 -0.01578 0.0878" quat="-2.59734e-06 0.707105 -2.59735e-06 -0.707108">
            <inertial pos="-0.00454299 0.0363693 0.00185256" quat="0.390924 0.319825 -0.413367 0.757639" mass="0.0800198" diaginertia="3.80714e-05 3.6141e-05 1.84916e-05"/>
            <joint name="rj4" pos="0 0 0" axis="0 0 1"/>
            <geom type="mesh" rgba="1 1 1 1" mesh="rl4"/>
            <body name="rl5" pos="-0.01 0.086 -0.013" quat="-2.59734e-06 -2.59735e-06 0.707108 0.707105">
              <inertial pos="0.000165241 -0.00261486 0.0359689" quat="0.697076 0.16416 -0.139166 0.683936" mass="0.0700033" diaginertia="2.47968e-05 2.14462e-05 1.42914e-05"/>
              <joint name="rj5" pos="0 0 0" axis="0 0 1"/>
              <geom type="mesh" rgba="1 1 1 1" mesh="rl5"/>
              <body name="rl6" pos="0 0.016 0.0568" quat="0.499998 -0.5 -0.5 -0.500002">
                <inertial pos="0.0248108 -0.0104126 -0.000898621" quat="0.384825 0.790751 0.324412 0.348395" mass="0.0753562" diaginertia="3.93978e-05 3.85245e-05 1.52341e-05"/>
                <joint name="rj6" pos="0 0 0" axis="0 0 1"/>
                <geom type="mesh" rgba="1 1 1 1" mesh="rl6"/>
                <body name="rl7" pos="0.046 0.039 -0.016" quat="-2.59734e-06 -2.59735e-06 0.707108 0.707105">
                  <inertial pos="-0.0501035 -0.0207212 -0.0338934" quat="0.46819 0.360554 0.398128 0.701636" mass="0.0739846" diaginertia="0.000164858 0.00014925 3.18554e-05"/>
                  <joint name="rj7" pos="0 0 0" axis="0 0 -1"/>
                  <geom type="mesh" rgba="1 1 1 1" mesh="rl7"/>
                </body>
              </body>
            </body>
          </body>
        </body>
      </body>
    </body>
  </worldbody>
</mujoco>
